Workbook

Sheet CLASIFICACIÓN
B2: JUGADOR | C2: PUNTUACIÓN
B3: {=_xlfn._xlws.SORT(_xlfn._xlws.FILTER(Puntuación_final!A2:C11, {1,0,1}), 2, -1)} -> TIBURON ROCA | C3: 35
B4: F3ROMONAS | C4: 30
B5: GUILLERMO | C5: 30
B6: DAVID | C6: 25
B7: JTORRESM | C7: 25
B8: Mike | C8: 25
B9: AESCOBARA | C9: 20
B10: DAMI | C10: 20
B11: JMONSALV | C11: 15
B12: SERGICM | C12: 15

Sheet Puntuación_final
A1: username | B1: user_id | C1: TOTAL PUNTOS | F1: username | G1: GOLES
A2: AESCOBARA | B2: d562c0c6-a625-4236-bdb6-3ff7530be80e | C2: =SUM(Pronósticos_de_partidos!L3,Clasificación_de_grupos!J3,Pronósticos_extra!G2,De_16_hasta_el_pódium!F3) -> 20 | F2: {=_xlfn._xlws.SORT(_xlfn.UNIQUE(_xlfn._xlws.FILTER(Aciertos!A2:A1048576, Aciertos!A2:A1048576<>"")))} -> AESCOBARA | G2: {=SUMIF(Aciertos!$A$2:$A$1048576,_xlfn.ANCHORARRAY( F2), Aciertos!$G$2:$G$1048576) + SUMIF(Aciertos!$A$2:$A$1048576,_xlfn.ANCHORARRAY( F2), Aciertos!$H$2:$H$1048576)} -> 12
A3: DAMI | B3: 8b15aca3-4ca4-419a-9572-9edfed0ee054 | C3: =SUM(Pronósticos_de_partidos!L77,Clasificación_de_grupos!J37,Pronósticos_extra!G3,De_16_hasta_el_pódium!F45) -> 20 | F3: DAMI | G3: 11
A4: DAVID | B4: 05baa4c9-babb-479e-89ad-a363bb4731e8 | C4: =SUM(Pronósticos_de_partidos!L151,Clasificación_de_grupos!J71,Pronósticos_extra!G4,De_16_hasta_el_pódium!F87) -> 25 | F4: DAVID | G4: 12
A5: F3ROMONAS | B5: 1e120ca7-b652-4e3d-9e05-a35fb495a661 | C5: =SUM(Pronósticos_de_partidos!L225,Clasificación_de_grupos!J105,Pronósticos_extra!G5,De_16_hasta_el_pódium!F129) -> 30 | F5: F3ROMONAS | G5: 13
A6: GUILLERMO | B6: 713d8068-0c77-4e2a-a816-a9ce4b9f9564 | C6: =SUM(Pronósticos_de_partidos!L299,Clasificación_de_grupos!J139,Pronósticos_extra!G6,De_16_hasta_el_pódium!F171) -> 30 | F6: GUILLERMO | G6: 13
A7: JMONSALV | B7: 89e5b4b5-385c-4eca-b932-3938537a170a | C7: =SUM(Pronósticos_de_partidos!L373,Clasificación_de_grupos!J173,Pronósticos_extra!G7,De_16_hasta_el_pódium!F213) -> 15 | F7: JMONSALV | G7: 8
A8: JTORRESM | B8: 4cddd374-e56f-40c3-8b51-f02b14da3dc7 | C8: =SUM(Pronósticos_de_partidos!L447,Clasificación_de_grupos!J207,Pronósticos_extra!G8,De_16_hasta_el_pódium!F255) -> 25 | F8: JTORRESM | G8: 9
A9: Mike | B9: 5312683a-abe0-400c-9a3d-8b8a4e1f1018 | C9: =SUM(Pronósticos_de_partidos!L521,Clasificación_de_grupos!J241,Pronósticos_extra!G9,De_16_hasta_el_pódium!F297) -> 25 | F9: Mike | G9: 14
A10: SERGICM | B10: 3983aafd-5f92-4e75-8bbc-07ab03ca0488 | C10: =SUM(Pronósticos_de_partidos!L595,Clasificación_de_grupos!J275,Pronósticos_extra!G10,De_16_hasta_el_pódium!F339) -> 15 | F10: SERGICM | G10: 6
A11: TIBURON ROCA | B11: 5f7a1833-45e0-4b3e-9716-6e1d370738b1 | C11: =SUM(Pronósticos_de_partidos!L669,Clasificación_de_grupos!J309,Pronósticos_extra!G11,De_16_hasta_el_pódium!F381) -> 35 | F11: TIBURON ROCA | G11: 22

Sheet Clasificación_de_grupos
A1: username | B1: group_stage | C1: posicion | D1: equipo | E1: pts | F1: gd | G1: gf | H1: tipo | I1: Puntuación | J1: TOTAL
A2: ★ AESCOBARA — 32 Selecciones
A3: AESCOBARA | B3: GROUP A | C3: 1 | D3: Mexico | E3: 7 | F3: 3 | G3: 5 | H3: CLASIFICADO | I3: =IF(COUNTIF(OFICIAL!$C$74:$D$88, D3) > 0, 1, 0) -> 0 | J3: =SUM(I3:I34) -> 0
A4: AESCOBARA | B4: GROUP A | C4: 2 | D4: South Korea | E4: 5 | F4: 3 | G4: 5 | H4: CLASIFICADO | I4: =IF(COUNTIF(OFICIAL!$C$74:$D$88, D4) > 0, 1, 0) -> 0
A5: AESCOBARA | B5: GROUP A | C5: 3 | D5: Czechia | E5: 4 | F5: 1 | G5: 4 | H5: MEJOR TERCERO | I5: =IF(COUNTIF(OFICIAL!$C$74:$D$88, D5) > 0, 1, 0) -> 0
A6: AESCOBARA | B6: GROUP B | C6: 1 | D6: Switzerland | E6: 9 | F6: 7 | G6: 7 | H6: CLASIFICADO | I6: =IF(COUNTIF(OFICIAL!$C$74:$D$88, D6) > 0, 1, 0) -> 0
A7: AESCOBARA | B7: GROUP B | C7: 2 | D7: Canada | E7: 4 | F7: -1 | G7: 3 | H7: CLASIFICADO | I7: =IF(COUNTIF(OFICIAL!$C$74:$D$88, D7) > 0, 1, 0) -> 0
A8: AESCOBARA | B8: GROUP C | C8: 1 | D8: Brazil | E8: 7 | F8: 5 | G8: 7 | H8: CLASIFICADO | I8: =IF(COUNTIF(OFICIAL!$C$74:$D$88, D8) > 0, 1, 0) -> 0
A9: AESCOBARA | B9: GROUP C | C9: 2 | D9: Morocco | E9: 6 | F9: 3 | G9: 6 | H9: CLASIFICADO | I9: =IF(COUNTIF(OFICIAL!$C$74:$D$88, D9) > 0, 1, 0) -> 0
A10: AESCOBARA | B10: GROUP C | C10: 3 | D10: Scotland | E10: 4 | F10: 1 | G10: 4 | H10: MEJOR TERCERO | I10: =IF(COUNTIF(OFICIAL!$C$74:$D$88, D10) > 0, 1, 0) -> 0
A11: AESCOBARA | B11: GROUP D | C11: 1 | D11: USA | E11: 7 | F11: 3 | G11: 5 | H11: CLASIFICADO | I11: =IF(COUNTIF(OFICIAL!$C$74:$D$88, D11) > 0, 1, 0) -> 0
A12: AESCOBARA | B12: GROUP D | C12: 2 | D12: Türkiye | E12: 7 | F12: 3 | G12: 4 | H12: CLASIFICADO | I12: =IF(COUNTIF(OFICIAL!$C$74:$D$88, D12) > 0, 1, 0) -> 0
A13: AESCOBARA | B13: GROUP E | C13: 1 | D13: Germany | E13: 7 | F13: 5 | G13: 8 | H13: CLASIFICADO | I13: =IF(COUNTIF(OFICIAL!$C$74:$D$88, D13) > 0, 1, 0) -> 0
A14: AESCOBARA | B14: GROUP E | C14: 2 | D14: Ivory Coast | E14: 5 | F14: 3 | G14: 6 | H14: CLASIFICADO | I14: =IF(COUNTIF(OFICIAL!$C$74:$D$88, D14) > 0, 1, 0) -> 0
A15: AESCOBARA | B15: GROUP E | C15: 3 | D15: Ecuador | E15: 4 | F15: 2 | G15: 5 | H15: MEJOR TERCERO | I15: =IF(COUNTIF(OFICIAL!$C$74:$D$88, D15) > 0, 1, 0) -> 0
... A34: AESCOBARA | B34: GROUP L | C34: 3 | D34: Ghana | E34: 4 | F34: 0 | G34: 4 | H34: MEJOR TERCERO | I34: =IF(COUNTIF(OFICIAL!$C$74:$D$88, D34) > 0, 1, 0) -> 0
A36: ★ DAMI — 32 Selecciones
A37: DAMI | B37: GROUP A | C37: 1 | D37: Mexico | E37: 7 | F37: 4 | G37: 5 | H37: CLASIFICADO | I37: =IF(COUNTIF(OFICIAL!$C$74:$D$88, D37) > 0, 1, 0) -> 0 | J37: =SUM(I37:I68) -> 0
A38: DAMI | B38: GROUP A | C38: 2 | D38: Czechia | E38: 5 | F38: 2 | G38: 4 | H38: CLASIFICADO | I38: =IF(COUNTIF(OFICIAL!$C$74:$D$88, D38) > 0, 1, 0) -> 0
A39: DAMI | B39: GROUP A | C39: 3 | D39: South Africa | E39: 4 | F39: 0 | G39: 4 | H39: MEJOR TERCERO | I39: =IF(COUNTIF(OFICIAL!$C$74:$D$88, D39) > 0, 1, 0) -> 0
A40: DAMI | B40: GROUP B | C40: 1 | D40: Canada | E40: 7 | F40: 2 | G40: 4 | H40: CLASIFICADO | I40: =IF(COUNTIF(OFICIAL!$C$74:$D$88, D40) > 0, 1, 0) -> 0
A41: DAMI | B41: GROUP B | C41: 2 | D41: Switzerland | E41: 5 | F41: 1 | G41: 4 | H41: CLASIFICADO | I41: =IF(COUNTIF(OFICIAL!$C$74:$D$88, D41) > 0, 1, 0) -> 0
A42: DAMI | B42: GROUP B | C42: 3 | D42: Qatar | E42: 4 | F42: 0 | G42: 2 | H42: MEJOR TERCERO | I42: =IF(COUNTIF(OFICIAL!$C$74:$D$88, D42) > 0, 1, 0) -> 0
A43: DAMI | B43: GROUP C | C43: 1 | D43: Morocco | E43: 9 | F43: 8 | G43: 9 | H43: CLASIFICADO | I43: =IF(COUNTIF(OFICIAL!$C$74:$D$88, D43) > 0, 1, 0) -> 0
A44: DAMI | B44: GROUP C | C44: 2 | D44: Brazil | E44: 6 | F44: 6 | G44: 10 | H44: CLASIFICADO | I44: =IF(COUNTIF(OFICIAL!$C$74:$D$88, D44) > 0, 1, 0) -> 0
A45: DAMI | B45: GROUP C | C45: 3 | D45: Scotland | E45: 3 | F45: -2 | G45: 3 | H45: MEJOR TERCERO | I45: =IF(COUNTIF(OFICIAL!$C$74:$D$88, D45) > 0, 1, 0) -> 0
A46: DAMI | B46: GROUP D | C46: 1 | D46: Türkiye | E46: 9 | F46: 5 | G46: 7 | H46: CLASIFICADO | I46: =IF(COUNTIF(OFICIAL!$C$74:$D$88, D46) > 0, 1, 0) -> 0
A47: DAMI | B47: GROUP D | C47: 2 | D47: USA | E47: 2 | F47: -1 | G47: 4 | H47: CLASIFICADO | I47: =IF(COUNTIF(OFICIAL!$C$74:$D$88, D47) > 0, 1, 0) -> 0
A48: DAMI | B48: GROUP E | C48: 1 | D48: Germany | E48: 9 | F48: 10 | G48: 11 | H48: CLASIFICADO | I48: =IF(COUNTIF(OFICIAL!$C$74:$D$88, D48) > 0, 1, 0) -> 0
A49: DAMI | B49: GROUP E | C49: 2 | D49: Ivory Coast | E49: 6 | F49: 2 | G49: 6 | H49: CLASIFICADO | I49: =IF(COUNTIF(OFICIAL!$C$74:$D$88, D49) > 0, 1, 0) -> 0
... A68: DAMI | B68: GROUP L | C68: 3 | D68: Ghana | E68: 3 | F68: 0 | G68: 4 | H68: MEJOR TERCERO | I68: =IF(COUNTIF(OFICIAL!$C$74:$D$88, D68) > 0, 1, 0) -> 0
A70: ★ DAVID — 32 Selecciones
A71: DAVID | B71: GROUP A | C71: 1 | D71: Mexico | E71: 9 | F71: 5 | G71: 6 | H71: CLASIFICADO | I71: =IF(COUNTIF(OFICIAL!$C$74:$D$88, D71) > 0, 1, 0) -> 0 | J71: =SUM(I71:I102) -> 0
A72: DAVID | B72: GROUP A | C72: 2 | D72: South Korea | E72: 4 | F72: 0 | G72: 3 | H72: CLASIFICADO | I72: =IF(COUNTIF(OFICIAL!$C$74:$D$88, D72) > 0, 1, 0) -> 0
A73: DAVID | B73: GROUP A | C73: 3 | D73: Czechia | E73: 2 | F73: -2 | G73: 2 | H73: MEJOR TERCERO | I73: =IF(COUNTIF(OFICIAL!$C$74:$D$88, D73) > 0, 1, 0) -> 0
A74: DAVID | B74: GROUP B | C74: 1 | D74: Switzerland | E74: 7 | F74: 4 | G74: 5 | H74: CLASIFICADO | I74: =IF(COUNTIF(OFICIAL!$C$74:$D$88, D74) > 0, 1, 0) -> 0
A75: DAVID | B75: GROUP B | C75: 2 | D75: Canada | E75: 7 | F75: 2 | G75: 5 | H75: CLASIFICADO | I75: =IF(COUNTIF(OFICIAL!$C$74:$D$88, D75) > 0, 1, 0) -> 0
A76: DAVID | B76: GROUP B | C76: 3 | D76: Bosnia and Herzegovina | E76: 3 | F76: -2 | G76: 2 | H76: MEJOR TERCERO | I76: =IF(COUNTIF(OFICIAL!$C$74:$D$88, D76) > 0, 1, 0) -> 0
A77: DAVID | B77: GROUP C | C77: 1 | D77: Brazil | E77: 9 | F77: 6 | G77: 7 | H77: CLASIFICADO | I77: =IF(COUNTIF(OFICIAL!$C$74:$D$88, D77) > 0, 1, 0) -> 0
A78: DAVID | B78: GROUP C | C78: 2 | D78: Morocco | E78: 6 | F78: 2 | G78: 5 | H78: CLASIFICADO | I78: =IF(COUNTIF(OFICIAL!$C$74:$D$88, D78) > 0, 1, 0) -> 0
...

Sheet Pronósticos_de_partidos
A1: username | B1: user_id | C1: match_id | D1: group_stage | E1: home_team | F1: away_team | G1: match_date | H1: prediction_home | I1: prediction_away | J1: fecha_pronostico | K1: Puntos | L1: TOTAL
A2: ★ AESCOBARA — 72 partidos
A3: AESCOBARA | B3: d562c0c6-a625-4236-bdb6-3ff7530be80e | C3: 508fde42-0d95-4deb-bb06-ffe8ed2063df | D3: GROUP A | E3: Mexico | F3: South Africa | G3: 2026-06-11 19:00:00+00 | H3: 2 | I3: 0 | J3: 2026-06-09 13:26:08.542963+00 | K3: =IF(AND(H3=OFICIAL!F2, I3=OFICIAL!G2), 5, 0) -> 5 | L3: =SUM(K3:K74) -> 20
A4: AESCOBARA | B4: d562c0c6-a625-4236-bdb6-3ff7530be80e | C4: 9a59f9b3-7047-4415-965f-60027d2b2f14 | D4: GROUP A | E4: South Korea | F4: Czechia | G4: 2026-06-12 02:00:00+00 | H4: 1 | I4: 1 | J4: 2026-06-09 13:26:08.542963+00 | K4: =IF(AND(H4=OFICIAL!F3, I4=OFICIAL!G3), 5, 0) -> 0
A5: AESCOBARA | B5: d562c0c6-a625-4236-bdb6-3ff7530be80e | C5: 786a6f9c-ec56-4cd6-8b44-8f0eed147c2b | D5: GROUP B | E5: Canada | F5: Bosnia and Herzegovina | G5: 2026-06-12 19:00:00+00 | H5: 2 | I5: 1 | J5: 2026-06-09 13:27:38.14446+00 | K5: =IF(AND(H5=OFICIAL!F4, I5=OFICIAL!G4), 5, 0) -> 0
A6: AESCOBARA | B6: d562c0c6-a625-4236-bdb6-3ff7530be80e | C6: d15b86b6-8131-4eed-9d08-f9941aaab68f | D6: GROUP D | E6: USA | F6: Paraguay | G6: 2026-06-13 01:00:00+00 | H6: 2 | I6: 0 | J6: 2026-06-09 14:28:47.66349+00 | K6: =IF(AND(H6=OFICIAL!F5, I6=OFICIAL!G5), 5, 0) -> 0
A7: AESCOBARA | B7: d562c0c6-a625-4236-bdb6-3ff7530be80e | C7: a966c60d-7b80-48d7-aaec-e45f740da490 | D7: GROUP B | E7: Qatar | F7: Switzerland | G7: 2026-06-13 19:00:00+00 | H7: 0 | I7: 3 | J7: 2026-06-09 13:27:38.14446+00 | K7: =IF(AND(H7=OFICIAL!F6, I7=OFICIAL!G6), 5, 0) -> 0
A8: AESCOBARA | B8: d562c0c6-a625-4236-bdb6-3ff7530be80e | C8: 6c0c01c5-d0b5-48a7-8066-7c03e4c9935b | D8: GROUP C | E8: Brazil | F8: Morocco | G8: 2026-06-13 22:00:00+00 | H8: 2 | I8: 1 | J8: 2026-06-09 13:29:29.786122+00 | K8: =IF(AND(H8=OFICIAL!F7, I8=OFICIAL!G7), 5, 0) -> 0
A9: AESCOBARA | B9: d562c0c6-a625-4236-bdb6-3ff7530be80e | C9: 0d0fecb5-49d5-4ade-893a-c03326a6ed99 | D9: GROUP C | E9: Haiti | F9: Scotland | G9: 2026-06-14 03:00:00+00 | H9: 0 | I9: 2 | J9: 2026-06-09 13:29:29.786122+00 | K9: =IF(AND(H9=OFICIAL!F8, I9=OFICIAL!G8), 5, 0) -> 0
A10: AESCOBARA | B10: d562c0c6-a625-4236-bdb6-3ff7530be80e | C10: 9562e7fe-3cc2-468b-8581-dfde5a600be4 | D10: GROUP D | E10: Australia | F10: Türkiye | G10: 2026-06-14 06:00:00+00 | H10: 0 | I10: 2 | J10: 2026-06-09 14:28:47.66349+00 | K10: =IF(AND(H10=OFICIAL!F9, I10=OFICIAL!G9), 5, 0) -> 0
A11: AESCOBARA | B11: d562c0c6-a625-4236-bdb6-3ff7530be80e | C11: 5deeae7a-b706-418b-99d7-042ef9ca05e5 | D11: GROUP E | E11: Germany | F11: Curaçao | G11: 2026-06-14 19:00:00+00 | H11: 4 | I11: 0 | J11: 2026-06-09 14:30:17.700381+00 | K11: =IF(AND(H11=OFICIAL!F10, I11=OFICIAL!G10), 5, 0) -> 0
A12: AESCOBARA | B12: d562c0c6-a625-4236-bdb6-3ff7530be80e | C12: 0d203b18-162c-4ca1-be32-6bc80bde86a7 | D12: GROUP F | E12: Netherlands | F12: Japan | G12: 2026-06-14 22:00:00+00 | H12: 2 | I12: 2 | J12: 2026-06-09 16:49:39.834349+00 | K12: =IF(AND(H12=OFICIAL!F11, I12=OFICIAL!G11), 5, 0) -> 5
A13: AESCOBARA | B13: d562c0c6-a625-4236-bdb6-3ff7530be80e | C13: b7a93904-fd26-43c7-bcf8-1b43f7f69e29 | D13: GROUP E | E13: Ivory Coast | F13: Ecuador | G13: 2026-06-15 01:00:00+00 | H13: 1 | I13: 1 | J13: 2026-06-09 14:30:17.700381+00 | K13: =IF(AND(H13=OFICIAL!F12, I13=OFICIAL!G12), 5, 0) -> 0
A14: AESCOBARA | B14: d562c0c6-a625-4236-bdb6-3ff7530be80e | C14: 41eb4eda-5a5f-43cf-bf68-771e0a04b8bd | D14: GROUP F | E14: Sweden | F14: Tunisia | G14: 2026-06-15 04:00:00+00 | H14: 2 | I14: 0 | J14: 2026-06-09 16:49:39.834349+00 | K14: =IF(AND(H14=OFICIAL!F13, I14=OFICIAL!G13), 5, 0) -> 0
A15: AESCOBARA | B15: d562c0c6-a625-4236-bdb6-3ff7530be80e | C15: 71fb781e-9423-4cb2-8fa6-e456891f4dd0 | D15: GROUP H | E15: Spain | F15: CAPE VERDE | G15: 2026-06-15 18:00:00+00 | H15: 3 | I15: 0 | J15: 2026-06-09 16:52:06.198951+00 | K15: =IF(AND(H15=OFICIAL!F14, I15=OFICIAL!G14), 5, 0) -> 0
... A74: AESCOBARA | B74: d562c0c6-a625-4236-bdb6-3ff7530be80e | C74: 6a93e346-d05d-4f0a-99e2-44659705424f | D74: GROUP J | E74: Algeria | F74: Austria | G74: 2026-06-28 02:00:00+00 | H74: 1 | I74: 1 | J74: 2026-06-09 16:55:51.80026+00 | K74: =IF(AND(H74=OFICIAL!F73, I74=OFICIAL!G73), 5, 0) -> 0
A76: ★ DAMI — 72 partidos
A77: DAMI | B77: 8b15aca3-4ca4-419a-9572-9edfed0ee054 | C77: 508fde42-0d95-4deb-bb06-ffe8ed2063df | D77: GROUP A | E77: Mexico | F77: South Africa | G77: 2026-06-11 19:00:00+00 | H77: 3 | I77: 1 | J77: 2026-06-05 16:53:17.199992+00 | K77: =IF(AND(H77=OFICIAL!F2, I77=OFICIAL!G2), 5, 0) -> 0 | L77: =SUM(K77:K148) -> 20
A78: DAMI | B78: 8b15aca3-4ca4-419a-9572-9edfed0ee054 | C78: 9a59f9b3-7047-4415-965f-60027d2b2f14 | D78: GROUP A | E78: South Korea | F78: Czechia | G78: 2026-06-12 02:00:00+00 | H78: 1 | I78: 3 | J78: 2026-06-05 16:53:17.199992+00 | K78: =IF(AND(H78=OFICIAL!F3, I78=OFICIAL!G3), 5, 0) -> 0
A79: DAMI | B79: 8b15aca3-4ca4-419a-9572-9edfed0ee054 | C79: 786a6f9c-ec56-4cd6-8b44-8f0eed147c2b | D79: GROUP B | E79: Canada | F79: Bosnia and Herzegovina | G79: 2026-06-12 19:00:00+00 | H79: 1 | I79: 0 | J79: 2026-06-05 16:54:13.451757+00 | K79: =IF(AND(H79=OFICIAL!F4, I79=OFICIAL!G4), 5, 0) -> 0
A80: DAMI | B80: 8b15aca3-4ca4-419a-9572-9edfed0ee054 | C80: d15b86b6-8131-4eed-9d08-f9941aaab68f | D80: GROUP D | E80: USA | F80: Paraguay | G80: 2026-06-13 01:00:00+00 | H80: 1 | I80: 1 | J80: 2026-06-05 16:55:37.145435+00 | K80: =IF(AND(H80=OFICIAL!F5, I80=OFICIAL!G5), 5, 0) -> 0
A81: DAMI | B81: 8b15aca3-4ca4-419a-9572-9edfed0ee054 | C81: a966c60d-7b80-48d7-aaec-e45f740da490 | D81: GROUP B | E81: Qatar | F81: Switzerland | G81: 2026-06-13 19:00:00+00 | H81: 0 | I81: 0 | J81: 2026-06-05 16:54:13.451757+00 | K81: =IF(AND(H81=OFICIAL!F6, I81=OFICIAL!G6), 5, 0) -> 0
A82: DAMI | B82: 8b15aca3-4ca4-419a-9572-9edfed0ee054 | C82: 6c0c01c5-d0b5-48a7-8066-7c03e4c9935b | D82: GROUP C | E82: Brazil | F82: Morocco | G82: 2026-06-13 22:00:00+00 | H82: 1 | I82: 2 | J82: 2026-06-05 16:54:55.874568+00 | K82: =IF(AND(H82=OFICIAL!F7, I82=OFICIAL!G7), 5, 0) -> 0
A83: DAMI | B83: 8b15aca3-4ca4-419a-9572-9edfed0ee054 | C83: 0d0fecb5-49d5-4ade-893a-c03326a6ed99 | D83: GROUP C | E83: Haiti | F83: Scotland | G83: 2026-06-14 03:00:00+00 | H83: 0 | I83: 2 | J83: 2026-06-05 16:54:55.874568+00 | K83: =IF(AND(H83=OFICIAL!F8, I83=OFICIAL!G8), 5, 0) -> 0
A84: DAMI | B84: 8b15aca3-4ca4-419a-9572-9edfed0ee054 | C84: 9562e7fe-3cc2-468b-8581-dfde5a600be4 | D84: GROUP D | E84: Australia | F84: Türkiye | G84: 2026-06-14 06:00:00+00 | H84: 0 | I84: 2 | J84: 2026-06-05 16:55:37.145435+00 | K84: =IF(AND(H84=OFICIAL!F9, I84=OFICIAL!G9), 5, 0) -> 0
A85: DAMI | B85: 8b15aca3-4ca4-419a-9572-9edfed0ee054 | C85: 5deeae7a-b706-418b-99d7-042ef9ca05e5 | D85: GROUP E | E85: Germany | F85: Curaçao | G85: 2026-06-14 19:00:00+00 | H85: 5 | I85: 0 | J85: 2026-06-05 16:56:12.817288+00 | K85: =IF(AND(H85=OFICIAL!F10, I85=OFICIAL!G10), 5, 0) -> 0
A86: DAMI | B86: 8b15aca3-4ca4-419a-9572-9edfed0ee054 | C86: 0d203b18-162c-4ca1-be32-6bc80bde86a7 | D86: GROUP F | E86: Netherlands | F86: Japan | G86: 2026-06-14 22:00:00+00 | H86: 3 | I86: 1 | J86: 2026-06-05 16:56:47.650995+00 | K86: =IF(AND(H86=OFICIAL!F11, I86=OFICIAL!G11), 5, 0) -> 0
A87: DAMI | B87: 8b15aca3-4ca4-419a-9572-9edfed0ee054 | C87: b7a93904-fd26-43c7-bcf8-1b43f7f69e29 | D87: GROUP E | E87: Ivory Coast | F87: Ecuador | G87: 2026-06-15 01:00:00+00 | H87: 2 | I87: 1 | J87: 2026-06-05 16:56:12.817288+00 | K87: =IF(AND(H87=OFICIAL!F12, I87=OFICIAL!G12), 5, 0) -> 0
A88: DAMI | B88: 8b15aca3-4ca4-419a-9572-9edfed0ee054 | C88: 41eb4eda-5a5f-43cf-bf68-771e0a04b8bd | D88: GROUP F | E88: Sweden | F88: Tunisia | G88: 2026-06-15 04:00:00+00 | H88: 2 | I88: 0 | J88: 2026-06-05 16:56:47.650995+00 | K88: =IF(AND(H88=OFICIAL!F13, I88=OFICIAL!G13), 5, 0) -> 0
A89: DAMI | B89: 8b15aca3-4ca4-419a-9572-9edfed0ee054 | C89: 71fb781e-9423-4cb2-8fa6-e456891f4dd0 | D89: GROUP H | E89: Spain | F89: CAPE VERDE | G89: 2026-06-15 18:00:00+00 | H89: 2 | I89: 0 | J89: 2026-06-05 16:58:28.560498+00 | K89: =IF(AND(H89=OFICIAL!F14, I89=OFICIAL!G14), 5, 0) -> 0
... A148: DAMI | B148: 8b15aca3-4ca4-419a-9572-9edfed0ee054 | C148: 6a93e346-d05d-4f0a-99e2-44659705424f | D148: GROUP J | E148: Algeria | F148: Austria | G148: 2026-06-28 02:00:00+00 | H148: 1 | I148: 2 | J148: 2026-06-05 16:59:43.856507+00 | K148: =IF(AND(H148=OFICIAL!F73, I148=OFICIAL!G73), 5, 0) -> 0
A150: ★ DAVID — 72 partidos
A151: DAVID | B151: 05baa4c9-babb-479e-89ad-a363bb4731e8 | C151: 508fde42-0d95-4deb-bb06-ffe8ed2063df | D151: GROUP A | E151: Mexico | F151: South Africa | G151: 2026-06-11 19:00:00+00 | H151: 2 | I151: 0 | J151: 2026-06-08 18:57:29.21685+00 | K151: =IF(AND(H151=OFICIAL!F2, I151=OFICIAL!G2), 5, 0) -> 5 | L151: =SUM(K151:K222) -> 25
A152: DAVID | B152: 05baa4c9-babb-479e-89ad-a363bb4731e8 | C152: 9a59f9b3-7047-4415-965f-60027d2b2f14 | D152: GROUP A | E152: South Korea | F152: Czechia | G152: 2026-06-12 02:00:00+00 | H152: 1 | I152: 1 | J152: 2026-06-08 18:57:29.21685+00 | K152: =IF(AND(H152=OFICIAL!F3, I152=OFICIAL!G3), 5, 0) -> 0
A153: DAVID | B153: 05baa4c9-babb-479e-89ad-a363bb4731e8 | C153: 786a6f9c-ec56-4cd6-8b44-8f0eed147c2b | D153: GROUP B | E153: Canada | F153: Bosnia and Herzegovina | G153: 2026-06-12 19:00:00+00 | H153: 2 | I153: 1 | J153: 2026-06-08 19:03:16.517508+00 | K153: =IF(AND(H153=OFICIAL!F4, I153=OFICIAL!G4), 5, 0) -> 0
A154: DAVID | B154: 05baa4c9-babb-479e-89ad-a363bb4731e8 | C154: d15b86b6-8131-4eed-9d08-f9941aaab68f | D154: GROUP D | E154: USA | F154: Paraguay | G154: 2026-06-13 01:00:00+00 | H154: 2 | I154: 0 | J154: 2026-06-08 19:06:46.850574+00 | K154: =IF(AND(H154=OFICIAL!F5, I154=OFICIAL!G5), 5, 0) -> 0
A155: DAVID | B155: 05baa4c9-babb-479e-89ad-a363bb4731e8 | C155: a966c60d-7b80-48d7-aaec-e45f740da490 | D155: GROUP B | E155: Qatar | F155: Switzerland | G155: 2026-06-13 19:00:00+00 | H155: 0 | I155: 2 | J155: 2026-06-08 19:03:16.517508+00 | K155: =IF(AND(H155=OFICIAL!F6, I155=OFICIAL!G6), 5, 0) -> 0
A156: DAVID | B156: 05baa4c9-babb-479e-89ad-a363bb4731e8 | C156: 6c0c01c5-d0b5-48a7-8066-7c03e4c9935b | D156: GROUP C | E156: Brazil | F156: Morocco | G156: 2026-06-13 22:00:00+00 | H156: 2 | I156: 1 | J156: 2026-06-08 19:05:38.954804+00 | K156: =IF(AND(H156=OFICIAL!F7, I156=OFICIAL!G7), 5, 0) -> 0
A157: DAVID | B157: 05baa4c9-babb-479e-89ad-a363bb4731e8 | C157: 0d0fecb5-49d5-4ade-893a-c03326a6ed99 | D157: GROUP C | E157: Haiti | F157: Scotland | G157: 2026-06-14 03:00:00+00 | H157: 1 | I157: 1 | J157: 2026-06-08 19:05:38.954804+00 | K157: =IF(AND(H157=OFICIAL!F8, I157=OFICIAL!G8), 5, 0) -> 0
A158: DAVID | B158: 05baa4c9-babb-479e-89ad-a363bb4731e8 | C158: 9562e7fe-3cc2-468b-8581-dfde5a600be4 | D158: GROUP D | E158: Australia | F158: Türkiye | G158: 2026-06-14 06:00:00+00 | H158: 1 | I158: 1 | J158: 2026-06-08 19:06:46.850574+00 | K158: =IF(AND(H158=OFICIAL!F9, I158=OFICIAL!G9), 5, 0) -> 0
...

Sheet Pronósticos_extra
A1: username | B1: best_player | C1: top_scorer | D1: best_keeper | E1: best_young | F1: fair_play | G1: Puntuación TOTAL
A2: AESCOBARA | B2: Kylian Mbappé (FRANCE) | C2: Harry Kane (ENGLAND) | D2: Mike Maignan (FRANCE) | E2: Lamine Yamal (SPAIN) | F2: JAPAN | G2: {=SUMPRODUCT(--(B2:F2=OFICIAL!K2:O2)) * 10} -> 0
A3: DAMI | B3: Michael Olise (FRANCE) | C3: KYLIAN MBAPPÉ (FRANCE) | D3: Yassine Bounou (MOROCCO) | E3: LAMINE YAMAL (SPAIN) | F3: USA | G3: {=SUMPRODUCT(--(B3:F3=OFICIAL!K2:O2)) * 10} -> 0
A4: DAVID | B4: Lamine Yamal (SPAIN) | C4: Kylian Mbappé (FRANCE) | D4: Emiliano Martínez (ARGENTINA) | E4: Lamine Yamal (SPAIN) | F4: JAPAN | G4: {=SUMPRODUCT(--(B4:F4=OFICIAL!K2:O2)) * 10} -> 0
A5: F3ROMONAS | B5: Lamine Yamal (SPAIN) | C5: Raphinha (BRAZIL) | D5: Unai Simón (SPAIN) | E5: Lamine Yamal (SPAIN) | F5: SPAIN | G5: {=SUMPRODUCT(--(B5:F5=OFICIAL!K2:O2)) * 10} -> 0
A6: GUILLERMO | B6: Lionel Messi (ARGENTINA) | C6: Kylian Mbappé (FRANCE) | D6: Emiliano Martínez (ARGENTINA) | E6: Lamine Yamal (SPAIN) | F6: GERMANY | G6: {=SUMPRODUCT(--(B6:F6=OFICIAL!K2:O2)) * 10} -> 0
A7: JMONSALV | B7: Lamine Yamal (SPAIN) | C7: Kylian Mbappé (FRANCE) | D7: Thibaut Courtois (BELGIUM) | E7: Lamine Yamal (SPAIN) | F7: SPAIN | G7: {=SUMPRODUCT(--(B7:F7=OFICIAL!K2:O2)) * 10} -> 0
A8: JTORRESM | B8: Kylian Mbappé (FRANCE) | C8: Harry Kane (ENGLAND) | D8: Unai Simón (SPAIN) | E8: Lamine Yamal (SPAIN) | F8: CURAÇAO | G8: {=SUMPRODUCT(--(B8:F8=OFICIAL!K2:O2)) * 10} -> 0
A9: Mike | B9: Raphinha (BRAZIL) | C9: Kylian Mbappé (FRANCE) | D9: Joan Garcia (SPAIN) | E9: Lamine Yamal (SPAIN) | F9: SPAIN | G9: {=SUMPRODUCT(--(B9:F9=OFICIAL!K2:O2)) * 10} -> 0
A10: SERGICM | B10: LAMINE YAMAL (SPAIN) | C10: KYLIAN MBAPPÉ (FRANCE) | D10: DIOGO COSTA (PORTUGAL) | E10: LAMINE YAMAL (SPAIN) | F10: USA | G10: {=SUMPRODUCT(--(B10:F10=OFICIAL!K2:O2)) * 10} -> 0
A11: TIBURON ROCA | B11: LAMINE YAMAL (SPAIN) | C11: HARRY KANE (ENGLAND) | D11: JORDAN PICKFORD (ENGLAND) | E11: LAMINE YAMAL (SPAIN) | F11: SAUDI ARABIA | G11: {=SUMPRODUCT(--(B11:F11=OFICIAL!K2:O2)) * 10} -> 0

Sheet De_16_hasta_el_pódium
A1: username | B1: match_id | C1: selected_team | D1: fecha_pronostico | E1: Puntos | F1: TOTAL | J1: =IF(COUNTIF(OFICIAL!$C$90:$D$97, H1) > 0, 1, 0) -> 0
A2: ★ AESCOBARA
A3: AESCOBARA | B3: 89_local | C3: Germany | D3: 2026-06-09 17:03:42.300698+00 | E3: =IF(COUNTIF(OFICIAL!$C$90:$D$97, C3) > 0, 2, 0) -> 0 | F3: =SUM(E3:E38) -> 0
A4: AESCOBARA | B4: 89_visitante | C4: France | D4: 2026-06-09 17:03:44.814999+00 | E4: =IF(COUNTIF(OFICIAL!$C$90:$D$97, C4) > 0, 2, 0) -> 0
A5: AESCOBARA | B5: 90_local | C5: Canada | D5: 2026-06-09 17:03:48.135951+00 | E5: =IF(COUNTIF(OFICIAL!$C$90:$D$97, C5) > 0, 2, 0) -> 0
A6: AESCOBARA | B6: 90_visitante | C6: Netherlands | D6: 2026-06-09 17:03:50.611728+00 | E6: =IF(COUNTIF(OFICIAL!$C$90:$D$97, C6) > 0, 2, 0) -> 0
A7: AESCOBARA | B7: 91_local | C7: Brazil | D7: 2026-06-09 17:03:52.878265+00 | E7: =IF(COUNTIF(OFICIAL!$C$90:$D$97, C7) > 0, 2, 0) -> 0
A8: AESCOBARA | B8: 91_visitante | C8: Senegal | D8: 2026-06-11 13:57:15.931141+00 | E8: =IF(COUNTIF(OFICIAL!$C$90:$D$97, C8) > 0, 2, 0) -> 0
A9: AESCOBARA | B9: 92_local | C9: Mexico | D9: 2026-06-11 13:57:15.931092+00 | E9: =IF(COUNTIF(OFICIAL!$C$90:$D$97, C9) > 0, 2, 0) -> 0
A10: AESCOBARA | B10: 92_visitante | C10: England | D10: 2026-06-11 13:57:15.931202+00 | E10: =IF(COUNTIF(OFICIAL!$C$90:$D$97, C10) > 0, 2, 0) -> 0
A11: AESCOBARA | B11: 93_local | C11: Portugal | D11: 2026-06-11 13:57:23.215508+00 | E11: =IF(COUNTIF(OFICIAL!$C$90:$D$97, C11) > 0, 2, 0) -> 0
A12: AESCOBARA | B12: 93_visitante | C12: Spain | D12: 2026-06-11 13:57:25.028764+00 | E12: =IF(COUNTIF(OFICIAL!$C$90:$D$97, C12) > 0, 2, 0) -> 0
A13: AESCOBARA | B13: 94_local | C13: USA | D13: 2026-06-11 13:57:29.044404+00 | E13: =IF(COUNTIF(OFICIAL!$C$90:$D$97, C13) > 0, 2, 0) -> 0
A14: AESCOBARA | B14: 94_visitante | C14: Belgium | D14: 2026-06-11 13:57:31.896886+00 | E14: =IF(COUNTIF(OFICIAL!$C$90:$D$97, C14) > 0, 2, 0) -> 0
A15: AESCOBARA | B15: 95_local | C15: Switzerland | D15: 2026-06-11 13:57:35.564172+00 | E15: =IF(COUNTIF(OFICIAL!$C$90:$D$97, C15) > 0, 2, 0) -> 0
... A18: AESCOBARA | B18: 96_visitante | C18: Egypt | D18: 2026-06-11 13:58:15.08989+00 | E18: =IF(COUNTIF(OFICIAL!$C$90:$D$97, C18) > 0, 2, 0) -> 0
A19: AESCOBARA | B19: 97_local | C19: France | D19: 2026-06-11 13:58:23.571405+00 | E19: =IF(COUNTIF(OFICIAL!$C$98:$D$101, C19) > 0, 4, 0) -> 0
A20: AESCOBARA | B20: 97_visitante | C20: Netherlands | D20: 2026-06-11 13:58:26.961855+00 | E20: =IF(COUNTIF(OFICIAL!$C$98:$D$101, C20) > 0, 4, 0) -> 0
A21: AESCOBARA | B21: 98_local | C21: Brazil | D21: 2026-06-11 13:58:30.195179+00 | E21: =IF(COUNTIF(OFICIAL!$C$98:$D$101, C21) > 0, 4, 0) -> 0
A22: AESCOBARA | B22: 98_visitante | C22: England | D22: 2026-06-11 13:58:32.939704+00 | E22: =IF(COUNTIF(OFICIAL!$C$98:$D$101, C22) > 0, 4, 0) -> 0
A23: AESCOBARA | B23: 99_local | C23: Spain | D23: 2026-06-11 13:58:36.402938+00 | E23: =IF(COUNTIF(OFICIAL!$C$98:$D$101, C23) > 0, 4, 0) -> 0
A24: AESCOBARA | B24: 99_visitante | C24: USA | D24: 2026-06-11 13:58:56.935294+00 | E24: =IF(COUNTIF(OFICIAL!$C$98:$D$101, C24) > 0, 4, 0) -> 0
A25: AESCOBARA | B25: 100_local | C25: Argentina | D25: 2026-06-11 13:59:12.398676+00 | E25: =IF(COUNTIF(OFICIAL!$C$98:$D$101, C25) > 0, 4, 0) -> 0
A26: AESCOBARA | B26: 100_visitante | C26: Colombia | D26: 2026-06-11 13:59:19.863218+00 | E26: =IF(COUNTIF(OFICIAL!$C$98:$D$101, C26) > 0, 4, 0) -> 0
A27: AESCOBARA | B27: 101_local | C27: France | D27: 2026-06-11 13:59:25.541662+00 | E27: =IF(COUNTIF(OFICIAL!$C$102:$D$103, C27) > 0, 8, 0) -> 0
A28: AESCOBARA | B28: 101_visitante | C28: England | D28: 2026-06-11 13:59:31.702973+00 | E28: =IF(COUNTIF(OFICIAL!$C$102:$D$103, C28) > 0, 8, 0) -> 0
A29: AESCOBARA | B29: 102_local | C29: Spain | D29: 2026-06-11 13:59:36.232644+00 | E29: =IF(COUNTIF(OFICIAL!$C$102:$D$103, C29) > 0, 8, 0) -> 0
A30: AESCOBARA | B30: 102_visitante | C30: Argentina | D30: 2026-06-11 13:59:39.058852+00 | E30: =IF(COUNTIF(OFICIAL!$C$102:$D$103, C30) > 0, 8, 0) -> 0
A31: AESCOBARA | B31: 103_local | C31: France | D31: 2026-06-11 14:00:15.546925+00 | E31: 0 | F31: NO PUNTUAN
A32: AESCOBARA | B32: 103_visitante | C32: Argentina | D32: 2026-06-11 14:00:17.879711+00 | E32: 0 | F32: NO PUNTUAN
A33: AESCOBARA | B33: 104_local | C33: England | D33: 2026-06-11 13:59:52.311113+00 | E33: =IF(COUNTIF(OFICIAL!$C$105:$D$105, C33) > 0, 10, 0) -> 0
A34: AESCOBARA | B34: 104_visitante | C34: Spain | D34: 2026-06-11 14:00:12.486181+00 | E34: =IF(COUNTIF(OFICIAL!$C$105:$D$105, C34) > 0, 10, 0) -> 0
A35: AESCOBARA | B35: podium_1 | C35: Spain | D35: 2026-06-11 14:00:30.747569+00 | E35: =IF(C35=OFICIAL!K5, 20, 0) -> 0
A36: AESCOBARA | B36: podium_2 | C36: England | D36: 2026-06-11 14:00:33.038017+00 | E36: 0 | F36: NO PUNTUAN
A37: AESCOBARA | B37: podium_3 | C37: Argentina | D37: 2026-06-11 14:00:59.829083+00 | E37: =IF(C37=OFICIAL!M5, 12, 0) -> 0
A38: AESCOBARA | B38: podium_4 | C38: France | D38: 2026-06-11 14:01:07.180679+00 | E38: 0 | F38: NO PUNTUAN
A40: ★ DAMI
A41: DAMI | B41: 89_local | C41: Germany | D41: 2026-06-11 12:15:13.622932+00 | E41: =IF(COUNTIF(OFICIAL!$C$90:$D$97, C41) > 0, 2, 0) -> 0 | F41: =SUM(E41:E76) -> 0
A42: DAMI | B42: 89_visitante | C42: France | D42: 2026-06-11 12:15:17.053424+00 | E42: =IF(COUNTIF(OFICIAL!$C$90:$D$97, C42) > 0, 2, 0) -> 0
A43: DAMI | B43: 90_local | C43: Switzerland | D43: 2026-06-11 12:15:21.886925+00 | E43: =IF(COUNTIF(OFICIAL!$C$90:$D$97, C43) > 0, 2, 0) -> 0
...

Sheet OFICIAL
A1: id | B1: group_stage | C1: home_team | D1: away_team | E1: match_date | F1: home_score | G1: away_score | H1: is_finished | J1: EXTRAS | K1: best_player | L1: top_scorer | M1: best_keeper | N1: best_young | O1: fair_play
A2: 508fde42-0d95-4deb-bb06-ffe8ed2063df | B2: GROUP A | C2: Mexico | D2: South Africa | E2: 2026-06-11 19:00:00+00 | F2: 2 | G2: 0 | H2: true
A3: 9a59f9b3-7047-4415-965f-60027d2b2f14 | B3: GROUP A | C3: South Korea | D3: Czechia | E3: 2026-06-12 02:00:00+00 | F3: 2 | G3: 1 | H3: true
A4: 786a6f9c-ec56-4cd6-8b44-8f0eed147c2b | B4: GROUP B | C4: Canada | D4: Bosnia and Herzegovina | E4: 2026-06-12 19:00:00+00 | F4: 1 | G4: 1 | H4: true | J4: PODIUM | K4: Campeón del Mundo | L4: Subcampeón | M4: Tercer Puesto | N4: Cuarto puesto
A5: d15b86b6-8131-4eed-9d08-f9941aaab68f | B5: GROUP D | C5: USA | D5: Paraguay | E5: 2026-06-13 01:00:00+00 | F5: 4 | G5: 1 | H5: true
A6: a966c60d-7b80-48d7-aaec-e45f740da490 | B6: GROUP B | C6: Qatar | D6: Switzerland | E6: 2026-06-13 19:00:00+00 | F6: 1 | G6: 1 | H6: true
A7: 6c0c01c5-d0b5-48a7-8066-7c03e4c9935b | B7: GROUP C | C7: Brazil | D7: Morocco | E7: 2026-06-13 22:00:00+00 | F7: 1 | G7: 1 | H7: true
A8: 0d0fecb5-49d5-4ade-893a-c03326a6ed99 | B8: GROUP C | C8: Haiti | D8: Scotland | E8: 2026-06-14 03:00:00+00 | F8: 0 | G8: 1 | H8: true
A9: 9562e7fe-3cc2-468b-8581-dfde5a600be4 | B9: GROUP D | C9: Australia | D9: Türkiye | E9: 2026-06-14 06:00:00+00 | F9: 2 | G9: 0 | H9: true
A10: 5deeae7a-b706-418b-99d7-042ef9ca05e5 | B10: GROUP E | C10: Germany | D10: Curaçao | E10: 2026-06-14 19:00:00+00 | F10: 7 | G10: 1 | H10: true
A11: 0d203b18-162c-4ca1-be32-6bc80bde86a7 | B11: GROUP F | C11: Netherlands | D11: Japan | E11: 2026-06-14 22:00:00+00 | F11: 2 | G11: 2 | H11: true
A12: b7a93904-fd26-43c7-bcf8-1b43f7f69e29 | B12: GROUP E | C12: Ivory Coast | D12: Ecuador | E12: 2026-06-15 01:00:00+00 | F12: 1 | G12: 0 | H12: true
A13: 41eb4eda-5a5f-43cf-bf68-771e0a04b8bd | B13: GROUP F | C13: Sweden | D13: Tunisia | E13: 2026-06-15 04:00:00+00 | F13: 5 | G13: 1 | H13: true
A14: 71fb781e-9423-4cb2-8fa6-e456891f4dd0 | B14: GROUP H | C14: Spain | D14: CAPE VERDE | E14: 2026-06-15 18:00:00+00 | F14: 0 | G14: 0 | H14: true
A15: bf9613bc-f036-4652-ab93-21c91530923c | B15: GROUP G | C15: Belgium | D15: Egypt | E15: 2026-06-15 21:00:00+00 | F15: 1 | G15: 1 | H15: true
A16: e7b11ce5-1ff6-4450-9e8b-a258e2914da8 | B16: GROUP H | C16: Saudi Arabia | D16: Uruguay | E16: 2026-06-16 00:00:00+00 | F16: 1 | G16: 1 | H16: true
... A49: 5cc28bc4-afe1-4f2b-943b-52e5c7a9bd97 | B49: GROUP K | C49: Congo DR | D49: Colombia | E49: 2026-06-24 02:00:00+00 | F49: 0 | G49: 1 | H49: false
A50: f274a3bc-165f-4d67-9484-34b83681d844 | B50: GROUP B | C50: Switzerland | D50: Canada | E50: 2026-06-24 19:00:00+00 | F50: null | G50: null | H50: false
A51: a6a6245c-601f-484b-a381-7e7623fe648d | B51: GROUP B | C51: Bosnia and Herzegovina | D51: Qatar | E51: 2026-06-24 19:00:00+00 | F51: null | G51: null | H51: false
A52: 3842d6ce-2774-4599-b099-2f48b40e7810 | B52: GROUP C | C52: Scotland | D52: Brazil | E52: 2026-06-24 22:00:00+00 | F52: null | G52: null | H52: false
A53: e8cdced1-61ad-47e9-8af6-bdacb05214a9 | B53: GROUP C | C53: Morocco | D53: Haiti | E53: 2026-06-24 22:00:00+00 | F53: null | G53: null | H53: false
A54: 35c8fde1-3470-446b-aa25-41eefa0d9a85 | B54: GROUP A | C54: South Korea | D54: South Africa | E54: 2026-06-25 01:00:00+00 | F54: null | G54: null | H54: false
A55: 4d807998-b338-414f-bcbb-cce1497ded16 | B55: GROUP A | C55: Czechia | D55: Mexico | E55: 2026-06-25 01:00:00+00 | F55: null | G55: null | H55: false
A56: 012930f4-468c-42b7-944c-74ac50c957f1 | B56: GROUP E | C56: Ecuador | D56: Germany | E56: 2026-06-25 20:00:00+00 | F56: null | G56: null | H56: false
A57: 83a9a7a8-66df-4e08-b5d3-30315e8ad5ce | B57: GROUP E | C57: Curaçao | D57: Ivory Coast | E57: 2026-06-25 20:00:00+00 | F57: null | G57: null | H57: false
A58: 3c6d2e2b-90bc-4ba5-adec-f383abb3e03f | B58: GROUP F | C58: Japan | D58: Sweden | E58: 2026-06-25 23:00:00+00 | F58: null | G58: null | H58: false
A59: 37f0bfe4-a5e3-49d4-9db3-bc09f782cc94 | B59: GROUP F | C59: Tunisia | D59: Netherlands | E59: 2026-06-25 23:00:00+00 | F59: null | G59: null | H59: false
A60: 94e3ccc0-6d65-40cb-a8fb-52d07cb7f65f | B60: GROUP D | C60: Türkiye | D60: USA | E60: 2026-06-26 02:00:00+00 | F60: null | G60: null | H60: false
A61: 66d4c18d-47c1-467c-affd-df0a47a6d7a1 | B61: GROUP D | C61: Paraguay | D61: Australia | E61: 2026-06-26 02:00:00+00 | F61: null | G61: null | H61: false
... A73: 9e7260c6-f6f7-4f3b-b3c2-aad3fd15d45b | B73: GROUP J | C73: Jordan | D73: Argentina | E73: 2026-06-28 02:00:00+00 | F73: null | G73: null | H73: false
A74: b818e642-85e4-4586-a98a-c2286f70ef5d | B74: ROUND 32 | E74: 2026-06-28 21:00:00+00 | F74: null | G74: null | H74: false
A75: 0e641f18-550d-4840-84c7-3307cc6f4b23 | B75: ROUND 32 | E75: 2026-06-29 19:00:00+00 | F75: null | G75: null | H75: false
A76: bd223b1d-05a1-469c-826e-ac1f54c9c421 | B76: ROUND 32 | E76: 2026-06-29 22:30:00+00 | F76: null | G76: null | H76: false
A77: 2cb3d19e-e2a5-44fe-977f-00804f7ad158 | B77: ROUND 32 | E77: 2026-06-30 03:00:00+00 | F77: null | G77: null | H77: false
A78: 9bf3844d-127a-428e-9159-5f35d5146f52 | B78: ROUND 32 | E78: 2026-06-30 19:00:00+00 | F78: null | G78: null | H78: false
A79: fb912c32-ecd9-498e-8111-450cd5094489 | B79: ROUND 32 | E79: 2026-06-30 23:00:00+00 | F79: null | G79: null | H79: false
A80: 12bd518b-b668-40b9-b4a9-4219a5030a5e | B80: ROUND 32 | E80: 2026-07-01 03:00:00+00 | F80: null | G80: null | H80: false
A81: a96afa81-6588-4066-aeb2-e41826fa0502 | B81: ROUND 32 | E81: 2026-07-01 18:00:00+00 | F81: null | G81: null | H81: false
A82: 7837ebbb-e2e7-4bed-ba71-1f62c57eec79 | B82: ROUND 32 | E82: 2026-07-01 22:00:00+00 | F82: null | G82: null | H82: false
A83: f2e13139-7a79-4384-a65e-9e98981a1cc0 | B83: ROUND 32 | E83: 2026-07-02 02:00:00+00 | F83: null | G83: null | H83: false
...

Sheet Aciertos
A1: username | B1: group_stage | C1: home_team | D1: away_team | E1: home_score | F1: away_score | G1: prediction_home | H1: prediction_away
A2: AESCOBARA | B2: GROUP A | C2: Mexico | D2: South Africa | E2: 2 | F2: 0 | G2: 2 | H2: 0
A3: AESCOBARA | B3: GROUP F | C3: Netherlands | D3: Japan | E3: 2 | F3: 2 | G3: 2 | H3: 2
A4: AESCOBARA | B4: GROUP G | C4: Belgium | D4: Egypt | E4: 1 | F4: 1 | G4: 1 | H4: 1
A5: AESCOBARA | B5: GROUP K | C5: Uzbekistan | D5: Colombia | E5: 1 | F5: 3 | G5: 1 | H5: 3
A6: DAMI | B6: GROUP G | C6: Belgium | D6: Egypt | E6: 1 | F6: 1 | G6: 1 | H6: 1
A7: DAMI | B7: GROUP J | C7: Argentina | D7: Algeria | E7: 3 | F7: 0 | G7: 3 | H7: 0
A8: DAMI | B8: GROUP K | C8: Uzbekistan | D8: Colombia | E8: 1 | F8: 3 | G8: 1 | H8: 3
A9: DAMI | B9: GROUP A | C9: South Africa | D9: Czechia | E9: 1 | F9: 1 | G9: 1 | H9: 1
A10: DAVID | B10: GROUP A | C10: Mexico | D10: South Africa | E10: 2 | F10: 0 | G10: 2 | H10: 0
A11: DAVID | B11: GROUP A | C11: South Africa | D11: Czechia | E11: 1 | F11: 1 | G11: 1 | H11: 1
A12: DAVID | B12: GROUP C | C12: Brazil | D12: Haiti | E12: 3 | F12: 0 | G12: 3 | H12: 0
A13: DAVID | B13: GROUP J | C13: Argentina | D13: Austria | E13: 2 | F13: 0 | G13: 2 | H13: 0
... A49: TIBURON ROCA | B49: GROUP J | C49: Algeria | D49: Jordan | E49: 2 | F49: 1 | G49: 2 | H49: 1

Sheet Hoja2
A1: id | B1: group_stage | C1: home_team | D1: away_team | E1: match_date | F1: home_score | G1: away_score | H1: is_finished
A2: 508fde42-0d95-4deb-bb06-ffe8ed2063df | B2: GROUP A | C2: Mexico | D2: South Africa | E2: 2026-06-11 19:00:00+00 | F2: 2 | G2: 0 | H2: true
A3: 9a59f9b3-7047-4415-965f-60027d2b2f14 | B3: GROUP A | C3: South Korea | D3: Czechia | E3: 2026-06-12 02:00:00+00 | F3: 2 | G3: 1 | H3: true
A4: 786a6f9c-ec56-4cd6-8b44-8f0eed147c2b | B4: GROUP B | C4: Canada | D4: Bosnia and Herzegovina | E4: 2026-06-12 19:00:00+00 | F4: 1 | G4: 1 | H4: true
A5: d15b86b6-8131-4eed-9d08-f9941aaab68f | B5: GROUP D | C5: USA | D5: Paraguay | E5: 2026-06-13 01:00:00+00 | F5: 4 | G5: 1 | H5: true
A6: a966c60d-7b80-48d7-aaec-e45f740da490 | B6: GROUP B | C6: Qatar | D6: Switzerland | E6: 2026-06-13 19:00:00+00 | F6: 1 | G6: 1 | H6: true
A7: 6c0c01c5-d0b5-48a7-8066-7c03e4c9935b | B7: GROUP C | C7: Brazil | D7: Morocco | E7: 2026-06-13 22:00:00+00 | F7: 1 | G7: 1 | H7: true
A8: 0d0fecb5-49d5-4ade-893a-c03326a6ed99 | B8: GROUP C | C8: Haiti | D8: Scotland | E8: 2026-06-14 03:00:00+00 | F8: 0 | G8: 1 | H8: true
A9: 9562e7fe-3cc2-468b-8581-dfde5a600be4 | B9: GROUP D | C9: Australia | D9: Türkiye | E9: 2026-06-14 06:00:00+00 | F9: 2 | G9: 0 | H9: true
A10: 5deeae7a-b706-418b-99d7-042ef9ca05e5 | B10: GROUP E | C10: Germany | D10: Curaçao | E10: 2026-06-14 19:00:00+00 | F10: 7 | G10: 1 | H10: true
A11: 0d203b18-162c-4ca1-be32-6bc80bde86a7 | B11: GROUP F | C11: Netherlands | D11: Japan | E11: 2026-06-14 22:00:00+00 | F11: 2 | G11: 2 | H11: true
A12: b7a93904-fd26-43c7-bcf8-1b43f7f69e29 | B12: GROUP E | C12: Ivory Coast | D12: Ecuador | E12: 2026-06-15 01:00:00+00 | F12: 1 | G12: 0 | H12: true
A13: 41eb4eda-5a5f-43cf-bf68-771e0a04b8bd | B13: GROUP F | C13: Sweden | D13: Tunisia | E13: 2026-06-15 04:00:00+00 | F13: 5 | G13: 1 | H13: true
... A49: 5cc28bc4-afe1-4f2b-943b-52e5c7a9bd97 | B49: GROUP K | C49: Congo DR | D49: Colombia | E49: 2026-06-24 02:00:00+00 | F49: 0 | G49: 1 | H49: true
A50: a6a6245c-601f-484b-a381-7e7623fe648d | B50: GROUP B | C50: Bosnia and Herzegovina | D50: Qatar | E50: 2026-06-24 19:00:00+00 | F50: null | G50: null | H50: false
A51: f274a3bc-165f-4d67-9484-34b83681d844 | B51: GROUP B | C51: Switzerland | D51: Canada | E51: 2026-06-24 19:00:00+00 | F51: null | G51: null | H51: false
A52: 3842d6ce-2774-4599-b099-2f48b40e7810 | B52: GROUP C | C52: Scotland | D52: Brazil | E52: 2026-06-24 22:00:00+00 | F52: null | G52: null | H52: false
A53: e8cdced1-61ad-47e9-8af6-bdacb05214a9 | B53: GROUP C | C53: Morocco | D53: Haiti | E53: 2026-06-24 22:00:00+00 | F53: null | G53: null | H53: false
A54: 35c8fde1-3470-446b-aa25-41eefa0d9a85 | B54: GROUP A | C54: South Korea | D54: South Africa | E54: 2026-06-25 01:00:00+00 | F54: null | G54: null | H54: false
A55: 4d807998-b338-414f-bcbb-cce1497ded16 | B55: GROUP A | C55: Czechia | D55: Mexico | E55: 2026-06-25 01:00:00+00 | F55: null | G55: null | H55: false
A56: 83a9a7a8-66df-4e08-b5d3-30315e8ad5ce | B56: GROUP E | C56: Curaçao | D56: Ivory Coast | E56: 2026-06-25 20:00:00+00 | F56: null | G56: null | H56: false
A57: 012930f4-468c-42b7-944c-74ac50c957f1 | B57: GROUP E | C57: Ecuador | D57: Germany | E57: 2026-06-25 20:00:00+00 | F57: null | G57: null | H57: false
A58: 37f0bfe4-a5e3-49d4-9db3-bc09f782cc94 | B58: GROUP F | C58: Tunisia | D58: Netherlands | E58: 2026-06-25 23:00:00+00 | F58: null | G58: null | H58: false
A59: 3c6d2e2b-90bc-4ba5-adec-f383abb3e03f | B59: GROUP F | C59: Japan | D59: Sweden | E59: 2026-06-25 23:00:00+00 | F59: null | G59: null | H59: false
A60: 66d4c18d-47c1-467c-affd-df0a47a6d7a1 | B60: GROUP D | C60: Paraguay | D60: Australia | E60: 2026-06-26 02:00:00+00 | F60: null | G60: null | H60: false
A61: 94e3ccc0-6d65-40cb-a8fb-52d07cb7f65f | B61: GROUP D | C61: Türkiye | D61: USA | E61: 2026-06-26 02:00:00+00 | F61: null | G61: null | H61: false
... A73: 6a93e346-d05d-4f0a-99e2-44659705424f | B73: GROUP J | C73: Algeria | D73: Austria | E73: 2026-06-28 02:00:00+00 | F73: null | G73: null | H73: false
A74: b818e642-85e4-4586-a98a-c2286f70ef5d | B74: ROUND 32 | E74: 2026-06-28 21:00:00+00 | F74: null | G74: null | H74: false
A75: 0e641f18-550d-4840-84c7-3307cc6f4b23 | B75: ROUND 32 | E75: 2026-06-29 19:00:00+00 | F75: null | G75: null | H75: false
A76: bd223b1d-05a1-469c-826e-ac1f54c9c421 | B76: ROUND 32 | E76: 2026-06-29 22:30:00+00 | F76: null | G76: null | H76: false
A77: 2cb3d19e-e2a5-44fe-977f-00804f7ad158 | B77: ROUND 32 | E77: 2026-06-30 03:00:00+00 | F77: null | G77: null | H77: false
A78: 9bf3844d-127a-428e-9159-5f35d5146f52 | B78: ROUND 32 | E78: 2026-06-30 19:00:00+00 | F78: null | G78: null | H78: false
A79: fb912c32-ecd9-498e-8111-450cd5094489 | B79: ROUND 32 | E79: 2026-06-30 23:00:00+00 | F79: null | G79: null | H79: false
A80: 12bd518b-b668-40b9-b4a9-4219a5030a5e | B80: ROUND 32 | E80: 2026-07-01 03:00:00+00 | F80: null | G80: null | H80: false
A81: a96afa81-6588-4066-aeb2-e41826fa0502 | B81: ROUND 32 | E81: 2026-07-01 18:00:00+00 | F81: null | G81: null | H81: false
A82: 7837ebbb-e2e7-4bed-ba71-1f62c57eec79 | B82: ROUND 32 | E82: 2026-07-01 22:00:00+00 | F82: null | G82: null | H82: false
A83: f2e13139-7a79-4384-a65e-9e98981a1cc0 | B83: ROUND 32 | E83: 2026-07-02 02:00:00+00 | F83: null | G83: null | H83: false
A84: 81474e30-9d99-4767-b3af-bd0ddb543f33 | B84: ROUND 32 | E84: 2026-07-02 21:00:00+00 | F84: null | G84: null | H84: false
A85: 2cce7477-a907-4521-8723-d4b4b62961dc | B85: ROUND 32 | E85: 2026-07-03 01:00:00+00 | F85: null | G85: null | H85: false
... A101: 5ebbd0f4-e4b9-4219-becc-90f25af1c707 | B101: QUARTER-FINAL | E101: 2026-07-12 03:00:00+00 | F101: null | G101: null | H101: false
